2023-09-23 18:48:49,468 INFO    StreamThr :4045 [internal.py:wandb_internal():86] W&B internal server running at pid: 4045, started at: 2023-09-23 18:48:49.467332
2023-09-23 18:48:49,469 DEBUG   HandlerThread:4045 [handler.py:handle_request():144] handle_request: status
2023-09-23 18:48:49,486 INFO    WriterThread:4045 [datastore.py:open_for_write():85] open: /Users/irshad/Dev/PyEnv/GTM-Transformer/wandb/run-20230923_184849-g40tfwnu/run-g40tfwnu.wandb
2023-09-23 18:48:49,486 DEBUG   SenderThread:4045 [sender.py:send():379] send: header
2023-09-23 18:48:49,515 DEBUG   SenderThread:4045 [sender.py:send():379] send: run
2023-09-23 18:48:50,157 ERROR   SenderThread:4045 [internal_api.py:execute():361] 404 response executing GraphQL.
2023-09-23 18:48:50,157 ERROR   SenderThread:4045 [internal_api.py:execute():362] {"errors":[{"message":"entity username-here not found during upsertBucket","path":["upsertBucket"]}],"data":{"upsertBucket":null}}
2023-09-23 18:48:50,158 ERROR   SenderThread:4045 [sender.py:send_run():976] It appears that you do not have permission to access the requested resource. Please reach out to the project owner to grant you access. If you have the correct permissions, verify that there are no issues with your networking setup.(Error 404: Not Found)
Traceback (most recent call last):
  File "/Users/irshad/Dev/PyEnv/env/lib/python3.8/site-packages/wandb/sdk/lib/retry.py", line 131, in __call__
    result = self._call_fn(*args, **kwargs)
  File "/Users/irshad/Dev/PyEnv/env/lib/python3.8/site-packages/wandb/sdk/internal/internal_api.py", line 358, in execute
    return self.client.execute(*args, **kwargs)  # type: ignore
  File "/Users/irshad/Dev/PyEnv/env/lib/python3.8/site-packages/wandb/vendor/gql-0.2.0/wandb_gql/client.py", line 52, in execute
    result = self._get_result(document, *args, **kwargs)
  File "/Users/irshad/Dev/PyEnv/env/lib/python3.8/site-packages/wandb/vendor/gql-0.2.0/wandb_gql/client.py", line 60, in _get_result
    return self.transport.execute(document, *args, **kwargs)
  File "/Users/irshad/Dev/PyEnv/env/lib/python3.8/site-packages/wandb/sdk/lib/gql_request.py", line 56, in execute
    request.raise_for_status()
  File "/Users/irshad/Dev/PyEnv/env/lib/python3.8/site-packages/requests/models.py", line 1021, in raise_for_status
    raise HTTPError(http_error_msg, response=self)
requests.exceptions.HTTPError: 404 Client Error: Not Found for url: https://api.wandb.ai/graphql

During handling of the above exception, another exception occurred:

Traceback (most recent call last):
  File "/Users/irshad/Dev/PyEnv/env/lib/python3.8/site-packages/wandb/sdk/internal/sender.py", line 974, in send_run
    self._init_run(run, config_value_dict)
  File "/Users/irshad/Dev/PyEnv/env/lib/python3.8/site-packages/wandb/sdk/internal/sender.py", line 1012, in _init_run
    server_run, inserted, server_messages = self._api.upsert_run(
  File "/Users/irshad/Dev/PyEnv/env/lib/python3.8/site-packages/wandb/apis/normalize.py", line 73, in wrapper
    raise err
  File "/Users/irshad/Dev/PyEnv/env/lib/python3.8/site-packages/wandb/apis/normalize.py", line 41, in wrapper
    return func(*args, **kwargs)
  File "/Users/irshad/Dev/PyEnv/env/lib/python3.8/site-packages/wandb/sdk/internal/internal_api.py", line 1999, in upsert_run
    response = self.gql(
  File "/Users/irshad/Dev/PyEnv/env/lib/python3.8/site-packages/wandb/sdk/internal/internal_api.py", line 330, in gql
    ret = self._retry_gql(
  File "/Users/irshad/Dev/PyEnv/env/lib/python3.8/site-packages/wandb/sdk/lib/retry.py", line 147, in __call__
    retry_timedelta_triggered = check_retry_fn(e)
  File "/Users/irshad/Dev/PyEnv/env/lib/python3.8/site-packages/wandb/util.py", line 964, in check_retry_fn
    return fallback_retry_fn(e)
  File "/Users/irshad/Dev/PyEnv/env/lib/python3.8/site-packages/wandb/util.py", line 906, in no_retry_auth
    raise CommError(
wandb.errors.CommError: It appears that you do not have permission to access the requested resource. Please reach out to the project owner to grant you access. If you have the correct permissions, verify that there are no issues with your networking setup.(Error 404: Not Found)
2023-09-23 18:48:50,446 DEBUG   HandlerThread:4045 [handler.py:handle_request():144] handle_request: shutdown
2023-09-23 18:48:50,447 INFO    HandlerThread:4045 [handler.py:finish():840] shutting down handler
2023-09-23 18:48:50,520 INFO    WriterThread:4045 [datastore.py:close():294] close: /Users/irshad/Dev/PyEnv/GTM-Transformer/wandb/run-20230923_184849-g40tfwnu/run-g40tfwnu.wandb
2023-09-23 18:48:51,169 INFO    SenderThread:4045 [sender.py:finish():1531] shutting down sender
